Workbook

Sheet Read Me
A1: PargoParcels — Enterprise Analytics Engineering Portfolio
A2: Synthetic SA last-mile logistics dataset | 11.06M rows generated (scales to 220M) | Postgres OLTP -> Snowflake -> dbt
A4: This workbook contains representative samples of every table plus a formula-driven KPI summary.
A7: Sheet | B7: Type | C7: Rows | D7: Description
A8: Parcels Sample | B8: fact | C8: 1,000 of 1,200,931 | D8: Parcel lifecycle w/ milestone timestamps; delivery & dwell hours are live formulas
A9: Tracking Events Sample | B9: fact | C9: 1,000 of 8,368,335 | D9: Scan-level event log (~7 events per parcel)
A10: Returns Sample | B10: fact | C10: 500 of 85,769 | D10: Returns w/ reason taxonomy
A11: Monthly Volumes | B11: aggregate | C11: 36 months | D11: Network volumes by month; totals are formulas
A12: Retailers | B12: dimension | C12: all 150 | D12: Clients incl. Bash, Woolworths, Clicks, Sportscene + tiers and rate cards
A13: Pickup Points Sample | B13: dimension | C13: 500 of 4,000 | D13: Pargo Point network across all 9 provinces
A14: Customers Sample | B14: dimension | C14: 500 of 400,000 | D14: Synthetic consumers (PII is fake)
A15: Couriers | B15: dimension | C15: all 500 | D15: Courier fleet w/ regions and vehicle types
A16: KPI Summary | B16: analysis | C16: — | D16: Formula-driven KPIs computed from the samples
A18: Data note: This Excel workbook uses representative samples for performance. Full dashboard/eBook figures can differ from workbook sample KPIs; ML metrics use held-out validation data and business impact values are modelled estimates.

Sheet KPI Summary
A1: Network KPIs — computed live from 'Parcels Sample' (1,000 parcels)
A3: KPI | B3: Value
A4: Parcels in sample | B4: =COUNTA('Parcels Sample'!A2:A871)
A5: Avg delivery hours (created → at point) | B5: =AVERAGE('Parcels Sample'!Q2:Q871)
A6: Avg delivery days | B6: =AVERAGE('Parcels Sample'!Q2:Q871)/24
A7: Avg dwell hours (at point → collected) | B7: =AVERAGE('Parcels Sample'!R2:R871)
A8: Delivery success rate | B8: =(COUNTIF('Parcels Sample'!K2:K871,"Collected")+COUNTIF('Parcels Sample'!K2:K871,"Damaged"))/COUNTA('Parcels Sample'!K2:K871)
A9: Returned-to-sender rate | B9: =COUNTIF('Parcels Sample'!K2:K871,"ExpiredRTS")/COUNTA('Parcels Sample'!K2:K871)
A10: 48h SLA achievement | B10: =COUNTIF('Parcels Sample'!Q2:Q871,"<=48")/COUNT('Parcels Sample'!Q2:Q871)
A11: Avg parcel value (ZAR) | B11: =AVERAGE('Parcels Sample'!N2:N871)
A12: Avg delivery cost (ZAR) | B12: =AVERAGE('Parcels Sample'!P2:P871)
A13: Total parcels, 36 months (full table) | B13: ='Monthly Volumes'!B38
A14: Network avg delivery hours (full table) | B14: ='Monthly Volumes'!C38
A16: Note: sample-based KPIs will differ slightly from full-table figures shown in the eBook.

Sheet Parcels Sample
A1: parcel_id | B1: waybill_number | C1: retailer_id | D1: pickup_point_id | E1: courier_id | F1: created_at | G1: dispatched_at | H1: arrived_at_point_at | I1: notified_at | J1: collected_at | K1: parcel_status | L1: service_type | M1: province | N1: parcel_value_zar | O1: parcel_weight_kg | P1: delivery_cost_zar | Q1: delivery_hours | R1: dwell_hours
A2: 2012 | B2: PGO10002012 | C2: 97 | D2: 2293 | E2: 420 | F2: 45110.223 | G2: 45110.507 | H2: 45111.141 | I2: 45111.176 | J2: 45112.73 | K2: Collected | L2: Standard | M2: Gauteng | N2: 604.66 | O2: 0.64 | P2: 47.32 | Q2: =IF(H2="","",(H2-F2)*24) | R2: =IF(J2="","",(J2-H2)*24)
A3: 13776 | B3: PGO10013776 | C3: 5 | D3: 2997 | E3: 446 | F3: 45110.362 | G3: 45110.395 | H3: 45111.138 | I3: 45111.142 | J3: 45116.357 | K3: Collected | L3: Standard | M3: Gauteng | N3: 339.62 | O3: 2.5 | P3: 57.42 | Q3: =IF(H3="","",(H3-F3)*24) | R3: =IF(J3="","",(J3-H3)*24)
A4: 18742 | B4: PGO10018742 | C4: 4 | D4: 1830 | E4: 108 | F4: 45110.963 | G4: 45111.46 | H4: 45112.606 | I4: 45112.648 | J4: 45113.967 | K4: Collected | L4: Standard | M4: North West | N4: 459.4 | O4: 1.2 | P4: 41.31 | Q4: =IF(H4="","",(H4-F4)*24) | R4: =IF(J4="","",(J4-H4)*24)
A5: 6856 | B5: PGO10006856 | C5: 68 | D5: 3651 | E5: 313 | F5: 45115.711 | G5: 45115.852 | H5: 45116.691 | I5: 45116.748 | J5: 45117.109 | K5: Collected | L5: Express | M5: Gauteng | N5: 244.26 | O5: 1.98 | P5: 60.35 | Q5: =IF(H5="","",(H5-F5)*24) | R5: =IF(J5="","",(J5-H5)*24)
A6: 14457 | B6: PGO10014457 | C6: 6 | D6: 3554 | E6: 383 | F6: 45116.915 | G6: 45117.211 | H6: 45118.015 | I6: 45118.039 | J6: 45118.393 | K6: Collected | L6: Standard | M6: Gauteng | N6: 129.32 | O6: 1.33 | P6: 41.15 | Q6: =IF(H6="","",(H6-F6)*24) | R6: =IF(J6="","",(J6-H6)*24)
A7: 22191 | B7: PGO10022191 | C7: 43 | D7: 1216 | E7: 155 | F7: 45118.316 | G7: 45118.545 | H7: 45119.568 | I7: 45119.621 | J7: 45121.486 | K7: Collected | L7: Standard | M7: Western Cape | N7: 62.69 | O7: 5.91 | P7: 73.95 | Q7: =IF(H7="","",(H7-F7)*24) | R7: =IF(J7="","",(J7-H7)*24)
A8: 1650 | B8: PGO10001650 | C8: 30 | D8: 3609 | E8: 147 | F8: 45120.951 | G8: 45121.422 | H8: 45122.543 | I8: 45122.581 | J8: 45123.078 | K8: Collected | L8: Standard | M8: Mpumalanga | N8: 170.54 | O8: 0.89 | P8: 69.13 | Q8: =IF(H8="","",(H8-F8)*24) | R8: =IF(J8="","",(J8-H8)*24)
A9: 9376 | B9: PGO10009376 | C9: 13 | D9: 2679 | E9: 109 | F9: 45123 | G9: 45123.823 | H9: 45124.505 | I9: 45124.523 | J9: 45125.919 | K9: Collected | L9: Standard | M9: Gauteng | N9: 366.6 | O9: 0.57 | P9: 68.15 | Q9: =IF(H9="","",(H9-F9)*24) | R9: =IF(J9="","",(J9-H9)*24)
A10: 16860 | B10: PGO10016860 | C10: 17 | D10: 1894 | E10: 217 | F10: 45125.246 | G10: 45125.641 | H10: 45126.71 | I10: 45126.72 | J10: 45128.059 | K10: Collected | L10: Standard | M10: KwaZulu-Natal | N10: 156.6 | O10: 5.8 | P10: 78.9 | Q10: =IF(H10="","",(H10-F10)*24) | R10: =IF(J10="","",(J10-H10)*24)
A11: 17093 | B11: PGO10017093 | C11: 47 | D11: 1190 | E11: 318 | F11: 45125.518 | G11: 45125.698 | H11: 45126.131 | I11: 45126.149 | J11: 45127.508 | K11: Collected | L11: Standard | M11: Limpopo | N11: 239.97 | O11: 0.5 | P11: 51.6 | Q11: =IF(H11="","",(H11-F11)*24) | R11: =IF(J11="","",(J11-H11)*24)
A12: 4121 | B12: PGO10004121 | C12: 3 | D12: 2698 | E12: 94 | F12: 45127.606 | G12: 45127.701 | H12: 45128.293 | I12: 45128.352 | J12: 45131.801 | K12: Collected | L12: Standard | M12: KwaZulu-Natal | N12: 65.79 | O12: 2.12 | P12: 40.45 | Q12: =IF(H12="","",(H12-F12)*24) | R12: =IF(J12="","",(J12-H12)*24)
A13: 13693 | B13: PGO10013693 | C13: 141 | D13: 1526 | E13: 381 | F13: 45128.146 | G13: 45128.415 | H13: 45129.144 | I13: 45129.192 | J13: 45130.418 | K13: Collected | L13: Standard | M13: North West | N13: 158.37 | O13: 0.84 | P13: 57.41 | Q13: =IF(H13="","",(H13-F13)*24) | R13: =IF(J13="","",(J13-H13)*24)
... A25: 23304 | B25: PGO10023304 | C25: 15 | D25: 276 | E25: 356 | F25: 45148.952 | G25: 45149.497 | H25: 45150.311 | I25: 45150.339 | J25: 45156.909 | K25: Collected | L25: Standard | M25: Gauteng | N25: 1965.48 | O25: 0.36 | P25: 62.71 | Q25: =IF(H25="","",(H25-F25)*24) | R25: =IF(J25="","",(J25-H25)*24)
A26: 37113 | B26: PGO10037113 | C26: 77 | D26: 2413 | E26: 18 | F26: 45149.446 | G26: 45149.523 | H26: 45150.497 | I26: 45150.507 | K26: ExpiredRTS | L26: Express | M26: KwaZulu-Natal | N26: 233.97 | O26: 3.31 | P26: 47.27 | Q26: =IF(H26="","",(H26-F26)*24) | R26: =IF(J26="","",(J26-H26)*24)
A27: 23054 | B27: PGO10023054 | C27: 4 | D27: 3236 | E27: 445 | F27: 45151.987 | G27: 45152.169 | H27: 45152.945 | I27: 45152.998 | J27: 45156.323 | K27: Collected | L27: Standard | M27: Gauteng | N27: 112.91 | O27: 1.03 | P27: 41.74 | Q27: =IF(H27="","",(H27-F27)*24) | R27: =IF(J27="","",(J27-H27)*24)
A28: 33447 | B28: PGO10033447 | C28: 2 | D28: 1297 | E28: 295 | F28: 45152.047 | G28: 45152.26 | H28: 45153.391 | I28: 45153.448 | J28: 45156.73 | K28: Collected | L28: Standard | M28: Eastern Cape | N28: 227.07 | O28: 1.44 | P28: 48.33 | Q28: =IF(H28="","",(H28-F28)*24) | R28: =IF(J28="","",(J28-H28)*24)
A29: 27616 | B29: PGO10027616 | C29: 111 | D29: 3878 | E29: 113 | F29: 45153.058 | G29: 45153.275 | H29: 45153.841 | I29: 45153.869 | J29: 45155.561 | K29: Collected | L29: Express | M29: Gauteng | N29: 269.18 | O29: 1.88 | P29: 62.48 | Q29: =IF(H29="","",(H29-F29)*24) | R29: =IF(J29="","",(J29-H29)*24)
A30: 24162 | B30: PGO10024162 | C30: 3 | D30: 3210 | E30: 317 | F30: 45155.051 | G30: 45155.167 | H30: 45155.681 | I30: 45155.685 | J30: 45156.883 | K30: Collected | L30: Standard | M30: Gauteng | N30: 276.71 | O30: 5.52 | P30: 53.7 | Q30: =IF(H30="","",(H30-F30)*24) | R30: =IF(J30="","",(J30-H30)*24)
A31: 44297 | B31: PGO10044297 | C31: 2 | D31: 3712 | E31: 191 | F31: 45155.751 | G31: 45155.981 | H31: 45156.781 | I31: 45156.838 | J31: 45157.048 | K31: Collected | L31: Standard | M31: Gauteng | N31: 201 | O31: 0.48 | P31: 51.06 | Q31: =IF(H31="","",(H31-F31)*24) | R31: =IF(J31="","",(J31-H31)*24)
A32: 35689 | B32: PGO10035689 | C32: 2 | D32: 676 | E32: 234 | F32: 45161.144 | G32: 45161.304 | H32: 45161.845 | I32: 45161.859 | J32: 45163.413 | K32: Collected | L32: Standard | M32: KwaZulu-Natal | N32: 157.3 | O32: 2.33 | P32: 48.12 | Q32: =IF(H32="","",(H32-F32)*24) | R32: =IF(J32="","",(J32-H32)*24)
A33: 31764 | B33: PGO10031764 | C33: 23 | D33: 1348 | E33: 217 | F33: 45162.827 | G33: 45162.861 | H33: 45164.15 | I33: 45164.187 | J33: 45165.615 | K33: Collected | L33: Standard | M33: KwaZulu-Natal | N33: 429.01 | O33: 5.43 | P33: 67.09 | Q33: =IF(H33="","",(H33-F33)*24) | R33: =IF(J33="","",(J33-H33)*24)
A34: 44982 | B34: PGO10044982 | C34: 26 | D34: 3557 | E34: 291 | F34: 45163.296 | G34: 45163.408 | H34: 45163.877 | I34: 45163.937 | J34: 45165.334 | K34: Collected | L34: Return-to-Retailer | M34: Gauteng | N34: 368.43 | O34: 0.83 | P34: 57.87 | Q34: =IF(H34="","",(H34-F34)*24) | R34: =IF(J34="","",(J34-H34)*24)
A35: 41799 | B35: PGO10041799 | C35: 31 | D35: 3754 | E35: 168 | F35: 45163.469 | G35: 45163.749 | H35: 45164.114 | I35: 45164.138 | J35: 45165.115 | K35: Collected | L35: Standard | M35: Gauteng | N35: 374.53 | O35: 0.11 | P35: 54.74 | Q35: =IF(H35="","",(H35-F35)*24) | R35: =IF(J35="","",(J35-H35)*24)
A36: 41559 | B36: PGO10041559 | C36: 20 | D36: 2177 | E36: 153 | F36: 45163.716 | G36: 45163.988 | H36: 45164.821 | I36: 45164.878 | J36: 45164.902 | K36: Collected | L36: Standard | M36: Limpopo | N36: 85.42 | O36: 0.25 | P36: 56.69 | Q36: =IF(H36="","",(H36-F36)*24) | R36: =IF(J36="","",(J36-H36)*24)
A37: 22952 | B37: PGO10022952 | C37: 3 | D37: 595 | E37: 272 | F37: 45164.15 | G37: 45164.252 | H37: 45165.009 | I37: 45165.049 | J37: 45165.746 | K37: Collected | L37: Standard | M37: Western Cape | N37: 270.01 | O37: 1.06 | P37: 39.28 | Q37: =IF(H37="","",(H37-F37)*24) | R37: =IF(J37="","",(J37-H37)*24)
A38: 36398 | B38: PGO10036398 | C38: 2 | D38: 479 | E38: 152 | F38: 45164.419 | G38: 45164.698 | H38: 45165.583 | I38: 45165.605 | J38: 45166.605 | K38: Collected | L38: Standard | M38: Mpumalanga | N38: 181.34 | O38: 2.61 | P38: 52.11 | Q38: =IF(H38="","",(H38-F38)*24) | R38: =IF(J38="","",(J38-H38)*24)
... A71: 85785 | B71: PGO10085785 | C71: 1 | D71: 162 | E71: 5 | F71: 45208.963 | G71: 45209.023 | H71: 45209.908 | I71: 45209.933 | J71: 45210.045 | K71: Collected | L71: Return-to-Retailer | M71: Gauteng | N71: 291.12 | O71: 0.19 | P71: 47.84 | Q71: =IF(H71="","",(H71-F71)*24) | R71: =IF(J71="","",(J71-H71)*24)
A72: 70243 | B72: PGO10070243 | C72: 78 | D72: 3887 | E72: 350 | F72: 45212.482 | G72: 45212.608 | H72: 45213.078 | I72: 45213.14 | K72: ExpiredRTS | L72: Standard | M72: Gauteng | N72: 144.81 | O72: 0.64 | P72: 66.09 | Q72: =IF(H72="","",(H72-F72)*24) | R72: =IF(J72="","",(J72-H72)*24)
A73: 69708 | B73: PGO10069708 | C73: 1 | D73: 3518 | E73: 379 | F73: 45219.286 | G73: 45219.742 | H73: 45220.017 | I73: 45220.029 | J73: 45222.991 | K73: Collected | L73: Standard | M73: Gauteng | N73: 381.13 | O73: 0.96 | P73: 46.66 | Q73: =IF(H73="","",(H73-F73)*24) | R73: =IF(J73="","",(J73-H73)*24)
A74: 77809 | B74: PGO10077809 | C74: 43 | D74: 3440 | E74: 59 | F74: 45219.907 | G74: 45220.137 | H74: 45220.91 | I74: 45220.92 | J74: 45221.122 | K74: Collected | L74: Express | M74: KwaZulu-Natal | N74: 220.92 | O74: 1.49 | P74: 51.43 | Q74: =IF(H74="","",(H74-F74)*24) | R74: =IF(J74="","",(J74-H74)*24)
A75: 90501 | B75: PGO10090501 | C75: 7 | D75: 2638 | E75: 316 | F75: 45221.676 | G75: 45221.937 | H75: 45222.605 | I75: 45222.615 | J75: 45223.074 | K75: Collected | L75: Standard | M75: KwaZulu-Natal | N75: 73.66 | O75: 2.42 | P75: 47.71 | Q75: =IF(H75="","",(H75-F75)*24) | R75: =IF(J75="","",(J75-H75)*24)
A76: 74697 | B76: PGO10074697 | C76: 6 | D76: 712 | E76: 459 | F76: 45226.293 | G76: 45226.305 | H76: 45226.716 | I76: 45226.752 | J76: 45228.992 | K76: Collected | L76: Standard | M76: Gauteng | N76: 155.58 | O76: 0.45 | P76: 41.8 | Q76: =IF(H76="","",(H76-F76)*24) | R76: =IF(J76="","",(J76-H76)*24)
A77: 89984 | B77: PGO10089984 | C77: 6 | D77: 2127 | E77: 252 | F77: 45226.356 | G77: 45226.686 | H77: 45227.12 | I77: 45227.155 | J77: 45227.595 | K77: Collected | L77: Express | M77: Mpumalanga | N77: 1172.55 | O77: 0.52 | P77: 40.75 | Q77: =IF(H77="","",(H77-F77)*24) | R77: =IF(J77="","",(J77-H77)*24)
A78: 83461 | B78: PGO10083461 | C78: 145 | D78: 2493 | E78: 22 | F78: 45228.752 | G78: 45228.8 | H78: 45229.299 | I78: 45229.306 | J78: 45230.38 | K78: Collected | L78: Standard | M78: Gauteng | N78: 84.54 | O78: 1.65 | P78: 53.64 | Q78: =IF(H78="","",(H78-F78)*24) | R78: =IF(J78="","",(J78-H78)*24)
A79: 75974 | B79: PGO10075974 | C79: 1 | D79: 64 | E79: 102 | F79: 45230.492 | G79: 45230.86 | H79: 45231.168 | I79: 45231.201 | J79: 45233.324 | K79: Collected | L79: Standard | M79: Gauteng | N79: 98.49 | O79: 1.7 | P79: 47.58 | Q79: =IF(H79="","",(H79-F79)*24) | R79: =IF(J79="","",(J79-H79)*24)
A80: 74375 | B80: PGO10074375 | C80: 7 | D80: 2905 | E80: 175 | F80: 45231.086 | G80: 45231.193 | H80: 45232.307 | I80: 45232.332 | J80: 45233.181 | K80: Collected | L80: Standard | M80: Mpumalanga | N80: 7042.62 | O80: 0.64 | P80: 49.59 | Q80: =IF(H80="","",(H80-F80)*24) | R80: =IF(J80="","",(J80-H80)*24)
A81: 100909 | B81: PGO10100909 | C81: 72 | D81: 3729 | E81: 312 | F81: 45235.526 | G81: 45235.571 | H81: 45236.992 | I81: 45237.033 | J81: 45238.408 | K81: Collected | L81: Standard | M81: Western Cape | N81: 162.37 | O81: 1.38 | P81: 61.95 | Q81: =IF(H81="","",(H81-F81)*24) | R81: =IF(J81="","",(J81-H81)*24)
A82: 129996 | B82: PGO10129996 | C82: 11 | D82: 1297 | E82: 355 | F82: 45235.568 | G82: 45235.642 | H82: 45236.648 | I82: 45236.694 | J82: 45237.579 | K82: Collected | L82: Standard | M82: Eastern Cape | N82: 57.45 | O82: 0.61 | P82: 65.7 | Q82: =IF(H82="","",(H82-F82)*24) | R82: =IF(J82="","",(J82-H82)*24)
A83: 119454 | B83: PGO10119454 | C83: 4 | D83: 329 | E83: 175 | F83: 45237.638 | G83: 45237.756 | H83: 45238.928 | I83: 45238.952 | J83: 45239.668 | K83: Collected | L83: Express | M83: Mpumalanga | N83: 494.16 | O83: 1.66 | P83: 44.09 | Q83: =IF(H83="","",(H83-F83)*24) | R83: =IF(J83="","",(J83-H83)*24)
...

Sheet Tracking Events Sample
A1: tracking_event_id | B1: parcel_id | C1: event_type | D1: event_timestamp | E1: latitude | F1: longitude | G1: status | H1: source_system | I1: month | J1: year
A2: 48260 | B2: 2650 | C2: AtHub | D2: 45115.649 | E2: -31.145083 | F2: 20.895831 | G2: Open | H2: API | I2: 07 | J2: 2023
A3: 120871 | B3: 6899 | C3: CustomerNotified | D3: 45116.335 | E3: -32.301949 | F3: 18.13506 | G3: Open | H3: ScannerApp | I3: 07 | J3: 2023
A4: 66277 | B4: 20667 | C4: AtHub | D4: 45117.234 | E4: -27.358276 | F4: 27.969543 | G4: Open | H4: PartnerPOS | I4: 07 | J4: 2023
A5: 119770 | B5: 5795 | C5: CustomerNotified | D5: 45118.128 | E5: -32.887358 | F5: 22.89965 | G5: Open | H5: ScannerApp | I5: 07 | J5: 2023
A6: 142280 | B6: 5971 | C6: CollectedByCustomer | D6: 45119.555 | E6: -30.405048 | F6: 18.797544 | G6: Closed | H6: CourierGPS | I6: 07 | J6: 2023
A7: 154550 | B7: 19263 | C7: CollectedByCustomer | D7: 45120.564 | E7: -31.884315 | F7: 28.564855 | G7: Closed | H7: ScannerApp | I7: 07 | J7: 2023
A8: 100864 | B8: 9663 | C8: ArrivedAtPickupPoint | D8: 45122.081 | E8: -25.931499 | F8: 31.33677 | G8: Open | H8: ScannerApp | I8: 07 | J8: 2023
A9: 23718 | B9: 913 | C9: CollectedFromRetailer | D9: 45122.801 | E9: -28.141681 | F9: 31.707802 | G9: Open | H9: API | I9: 07 | J9: 2023
A10: 103434 | B10: 12237 | C10: ArrivedAtPickupPoint | D10: 45122.976 | E10: -26.377128 | F10: 27.247982 | G10: Open | H10: PartnerPOS | I10: 07 | J10: 2023
A11: 28216 | B11: 5411 | C11: CollectedFromRetailer | D11: 45128.268 | E11: -27.502123 | F11: 27.83833 | G11: Open | H11: API | I11: 07 | J11: 2023
A12: 103683 | B12: 12487 | C12: ArrivedAtPickupPoint | D12: 45129.002 | E12: -33.722387 | F12: 19.024572 | G12: Open | H12: PartnerPOS | I12: 07 | J12: 2023
A13: 119730 | B13: 5755 | C13: CustomerNotified | D13: 45129.709 | E13: -25.201989 | F13: 27.340555 | G13: Open | H13: PartnerPOS | I13: 07 | J13: 2023
... A1001: 8360464 | B1001: 1194880 | C1001: CollectedByCustomer | D1001: 46204.706 | E1001: -26.867855 | F1001: 27.020902 | G1001: Closed | H1001: ScannerApp | I1001: 06 | J1001: 2026

Sheet Returns Sample
A1: return_id | B1: parcel_id | C1: retailer_id | D1: return_initiated_at | E1: return_reason | F1: return_value_zar | G1: drop_off_point_id | H1: month | I1: year
A2: 751 | B2: 10341 | C2: 149 | D2: 45114.37 | E2: Wrong size | F2: 176.89 | G2: 433 | H2: 07 | I2: 2023
A3: 1034 | B3: 14234 | C3: 56 | D3: 45118.922 | E3: Wrong size | F3: 370.29 | G3: 1873 | H3: 07 | I3: 2023
A4: 677 | B4: 9130 | C4: 82 | D4: 45121.684 | E4: Wrong size | F4: 288.67 | G4: 2212 | H4: 07 | I4: 2023
A5: 64 | B5: 983 | C5: 1 | D5: 45122.463 | E5: Wrong size | F5: 232.09 | G5: 2911 | H5: 07 | I5: 2023
A6: 676 | B6: 9099 | C6: 3 | D6: 45137.966 | E6: Wrong size | F6: 246.79 | G6: 579 | H6: 07 | I6: 2023
A7: 1557 | B7: 21459 | C7: 65 | D7: 45138.018 | E7: Changed mind | F7: 22.21 | G7: 3554 | H7: 07 | I7: 2023
A8: 462 | B8: 6101 | C8: 7 | D8: 45139.489 | E8: Changed mind | F8: 292.11 | G8: 1828 | H8: 07 | I8: 2023
A9: 1206 | B9: 16892 | C9: 4 | D9: 45143.46 | E9: Wrong size | F9: 69.71 | G9: 2969 | H9: 07 | I9: 2023
A10: 672 | B10: 9069 | C10: 29 | D10: 45144.006 | E10: Wrong size | F10: 79.36 | G10: 3585 | H10: 07 | I10: 2023
A11: 2571 | B11: 35912 | C11: 1 | D11: 45154.003 | E11: Changed mind | F11: 1859.6 | G11: 778 | H11: 08 | I11: 2023
A12: 2426 | B12: 34003 | C12: 7 | D12: 45157.936 | E12: Wrong size | F12: 422.41 | G12: 2146 | H12: 08 | I12: 2023
A13: 2469 | B13: 34599 | C13: 5 | D13: 45158.089 | E13: Item damaged | F13: 548.11 | G13: 2064 | H13: 08 | I13: 2023
... A501: 83371 | B501: 1162683 | C501: 52 | D501: 46205.318 | E501: Wrong size | F501: 48.08 | G501: 2973 | H501: 06 | I501: 2026

Sheet Monthly Volumes
A1: month | B1: parcels | C1: avg_delivery_hours | D1: delivered | E1: rts | F1: lost
A2: 2023-07 | B2: 22309 | C2: 26.9 | D2: 20625 | E2: 1236 | F2: 39
A3: 2023-08 | B3: 22338 | C3: 26.9 | D3: 20645 | E3: 1208 | F3: 38
A4: 2023-09 | B4: 22750 | C4: 27 | D4: 20972 | E4: 1273 | F4: 48
A5: 2023-10 | B5: 23406 | C5: 26.8 | D5: 21610 | E5: 1271 | F5: 40
A6: 2023-11 | B6: 43780 | C6: 26.8 | D6: 40397 | E6: 2430 | F6: 67
A7: 2023-12 | B7: 35682 | C7: 26.8 | D7: 32885 | E7: 1997 | F7: 71
A8: 2024-01 | B8: 17870 | C8: 26.9 | D8: 16433 | E8: 1006 | F8: 39
A9: 2024-02 | B9: 20306 | C9: 27 | D9: 18669 | E9: 1171 | F9: 44
A10: 2024-03 | B10: 26010 | C10: 27 | D10: 23969 | E10: 1450 | F10: 52
A11: 2024-04 | B11: 26601 | C11: 26.9 | D11: 24524 | E11: 1487 | F11: 68
A12: 2024-05 | B12: 27173 | C12: 26.9 | D12: 25104 | E12: 1494 | F12: 58
A13: 2024-06 | B13: 27720 | C13: 26.8 | D13: 25550 | E13: 1553 | F13: 50
... A37: 2026-06 | B37: 40812 | C37: 26.9 | D37: 34003 | E37: 1977 | F37: 76
A38: TOTAL / AVG | B38: =SUM(B2:B37) | C38: =AVERAGE(C2:C37) | D38: =SUM(D2:D37) | E38: =SUM(E2:E37) | F38: =SUM(F2:F37)

Sheet Retailers
A1: retailer_id | B1: retailer_name | C1: industry | D1: tier | E1: contract_start_date | F1: rate_per_parcel_zar | G1: integration_type
A2: 1 | B2: Bash | C2: Fashion & Apparel | D2: Enterprise | E2: 45108 | F2: 46.24 | G2: API
A3: 2 | B3: Woolworths | C3: Retail - Premium | D3: Enterprise | E3: 43705 | F3: 49.85 | G3: API
A4: 3 | B4: Clicks | C4: Health & Pharmacy | D4: Enterprise | E4: 43683 | F4: 38.81 | G4: API
A5: 4 | B5: Sportscene | C5: Fashion & Apparel | D5: Enterprise | E5: 43738 | F5: 43.23 | G5: WooCommerce Plugin
A6: 5 | B6: FILA South Africa | C6: Fashion & Apparel | D6: Mid-Market | E6: 44742 | F6: 56.77 | G6: API
A7: 6 | B7: Cape Union Mart | C7: Outdoor & Lifestyle | D7: Enterprise | E7: 44560 | F7: 40.26 | G7: WooCommerce Plugin
A8: 7 | B8: OneDayOnly | C8: E-commerce Marketplace | D8: Enterprise | E8: 45108 | F8: 49.43 | G8: Manual Portal
A9: 8 | B9: Loot.co.za | C9: E-commerce Marketplace | D9: Mid-Market | E9: 44164 | F9: 56.11 | G9: API
A10: 9 | B10: Wellness Warehouse | C10: Health & Pharmacy | D10: Mid-Market | E10: 43822 | F10: 57.54 | G10: API
A11: 10 | B11: Griffiths SA | C11: Home & Garden | D11: SMB | E11: 43226 | F11: 63.29 | G11: Shopify Plugin
A12: 11 | B12: Newman Ltd Direct | C12: Retail - Premium | D12: SMB | E12: 43119 | F12: 67.44 | G12: API
A13: 12 | B13: Norman Online | C13: Fashion & Apparel | D13: SMB | E13: 44055 | F13: 68.21 | G13: API
... A151: 150 | B151: Kennedy Inc Direct | C151: Fashion & Apparel | D151: Mid-Market | E151: 45052 | F151: 54.14 | G151: API

Sheet Pickup Points Sample
A1: pickup_point_id | B1: store_name | C1: partner_name | D1: province | E1: city | F1: latitude | G1: longitude | H1: opening_date | I1: capacity_per_day | J1: status
A2: 314 | B2: Clicks Newcastle Mall | C2: Clicks | D2: KwaZulu-Natal | E2: Newcastle | F2: -27.384111 | G2: 29.026651 | H2: 44220 | I2: 35 | J2: Active
A3: 3489 | B3: Clicks Umhlanga | C3: Clicks | D3: KwaZulu-Natal | E3: Umhlanga | F3: -27.951628 | G3: 29.043078 | H3: 42447 | I3: 35 | J3: Active
A4: 2731 | B4: Lewis Polokwane Square | C4: Lewis | D4: Limpopo | E4: Polokwane | F4: -22.885509 | G4: 27.416431 | H4: 44684 | I4: 50 | J4: Active
A5: 193 | B5: PEP Tzaneen Central | C5: PEP | D5: Limpopo | E5: Tzaneen | F5: -22.343412 | G5: 30.84085 | H5: 44305 | I5: 20 | J5: Active
A6: 3066 | B6: PostNet Mokopane Plaza | C6: PostNet | D6: Limpopo | E6: Mokopane | F6: -24.688662 | G6: 27.152757 | H6: 44639 | I6: 80 | J6: Active
A7: 1374 | B7: Caltex Freshstop Roodepoort Mall | C7: Caltex Freshstop | D7: Gauteng | E7: Roodepoort | F7: -25.207415 | G7: 27.486037 | H7: 42702 | I7: 80 | J7: Active
A8: 2056 | B8: Clicks Cape Town | C8: Clicks | D8: Western Cape | E8: Cape Town | F8: -32.155526 | G8: 20.092185 | H8: 44183 | I8: 35 | J8: Active
A9: 3343 | B9: PEP Somerset West Central | C9: PEP | D9: Western Cape | E9: Somerset West | F9: -31.632267 | G9: 22.07496 | H9: 43642 | I9: 120 | J9: Active
A10: 552 | B10: Clicks Bellville | C10: Clicks | D10: Western Cape | E10: Bellville | F10: -32.691228 | G10: 21.068475 | H10: 43325 | I10: 80 | J10: Active
A11: 3863 | B11: Build it Mokopane Park | C11: Build it | D11: Limpopo | E11: Mokopane | F11: -24.892049 | G11: 30.306525 | H11: 44791 | I11: 35 | J11: Active
A12: 753 | B12: Clicks Cape Town Park | C12: Clicks | D12: Western Cape | E12: Cape Town | F12: -33.631004 | G12: 22.582231 | H12: 44326 | I12: 20 | J12: Active
A13: 1548 | B13: Build it Bellville Square | C13: Build it | D13: Western Cape | E13: Bellville | F13: -31.598204 | G13: 18.468107 | H13: 42869 | I13: 120 | J13: Active
... A501: 2599 | B501: Lewis Pretoria Park | C501: Lewis | D501: Gauteng | E501: Pretoria | F501: -25.48058 | G501: 28.16476 | H501: 44500 | I501: 80 | J501: Active

Sheet Customers Sample
A1: customer_id | B1: customer_name | C1: mobile_number | D1: province | E1: city | F1: registration_date | G1: customer_segment | H1: active_flag
A2: 56103 | B2: Nomvula Mokoena | C2: +27475272027 | D2: Western Cape | E2: Somerset West | F2: 45654 | G2: Occasional | H2: =FALSE()
A3: 240102 | B3: Naledi Venter | C3: +27475619679 | D3: Northern Cape | E3: Kimberley | F3: 44968 | G3: Frequent | H3: =TRUE()
A4: 397221 | B4: Refilwe Pretorius | C4: +27472485583 | D4: Eastern Cape | E4: East London | F4: 44444 | G4: Dormant | H4: =TRUE()
A5: 245223 | B5: Chloe Tshabalala | C5: +27478125850 | D5: KwaZulu-Natal | E5: Durban | F5: 45328 | G5: Occasional | H5: =TRUE()
A6: 81961 | B6: Johan Fourie | C6: +27473348452 | D6: KwaZulu-Natal | E6: Durban | F6: 45443 | G6: Occasional | H6: =TRUE()
A7: 329319 | B7: Chloe Pretorius | C7: +27475700838 | D7: Gauteng | E7: Johannesburg | F7: 45950 | G7: Dormant | H7: =TRUE()
A8: 183559 | B8: Fatima Zulu | C8: +27479417885 | D8: Eastern Cape | E8: Mthatha | F8: 45931 | G8: Occasional | H8: =TRUE()
A9: 79163 | B9: Riaan Venter | C9: +27473516308 | D9: Mpumalanga | E9: Middelburg | F9: 45063 | G9: Frequent | H9: =TRUE()
A10: 138982 | B10: Dineo Ngcobo | C10: +27473895160 | D10: Eastern Cape | E10: Mthatha | F10: 45157 | G10: Occasional | H10: =TRUE()
A11: 243314 | B11: Zanele Pretorius | C11: +27475897500 | D11: North West | E11: Klerksdorp | F11: 45104 | G11: Regular | H11: =TRUE()
A12: 271725 | B12: Khanyi Dlamini | C12: +27472325079 | D12: Free State | E12: Welkom | F12: 45359 | G12: Occasional | H12: =TRUE()
A13: 223228 | B13: Kagiso Smith | C13: +27474748698 | D13: Western Cape | E13: Paarl | F13: 44587 | G13: Dormant | H13: =TRUE()
A14: 339752 | B14: Liam Mabaso | C14: +27479785422 | D14: Western Cape | E14: Table View | F14: 44918 | G14: Occasional | H14: =TRUE()
... A24: 43550 | B24: Lerato Botha | C24: +27471390516 | D24: Western Cape | E24: Somerset West | F24: 45346 | G24: Dormant | H24: =TRUE()
A25: 37471 | B25: Pieter Mahlangu | C25: +27476650829 | D25: Western Cape | E25: Paarl | F25: 46198 | G25: Frequent | H25: =FALSE()
A26: 45761 | B26: Daniel Zulu | C26: +27479220332 | D26: Western Cape | E26: George | F26: 45103 | G26: Regular | H26: =TRUE()
A27: 257827 | B27: Zanele Pillay | C27: +27477102531 | D27: Western Cape | E27: George | F27: 44943 | G27: Dormant | H27: =TRUE()
A28: 320287 | B28: Mandla Ngcobo | C28: +27477011744 | D28: Free State | E28: Bloemfontein | F28: 45155 | G28: Occasional | H28: =TRUE()
A29: 315444 | B29: Bongani Adams | C29: +27472070911 | D29: Limpopo | E29: Tzaneen | F29: 46073 | G29: Regular | H29: =TRUE()
A30: 101907 | B30: Nomvula Steyn | C30: +27475236898 | D30: Eastern Cape | E30: Uitenhage | F30: 44424 | G30: Occasional | H30: =FALSE()
A31: 199351 | B31: Dineo Fourie | C31: +27471173295 | D31: Eastern Cape | E31: Gqeberha | F31: 45108 | G31: Dormant | H31: =TRUE()
A32: 262797 | B32: Dineo Khumalo | C32: +27473766683 | D32: Northern Cape | E32: Springbok | F32: 45768 | G32: Occasional | H32: =TRUE()
A33: 102041 | B33: Sarah Nkosi | C33: +27472832364 | D33: KwaZulu-Natal | E33: Newcastle | F33: 45161 | G33: Frequent | H33: =TRUE()
A34: 314147 | B34: Lwazi Petersen | C34: +27478714817 | D34: KwaZulu-Natal | E34: Durban | F34: 45539 | G34: Occasional | H34: =TRUE()
A35: 334075 | B35: Zanele Molefe | C35: +27471062156 | D35: Gauteng | E35: Roodepoort | F35: 45486 | G35: Regular | H35: =TRUE()
A36: 209696 | B36: Riaan Dlamini | C36: +27473672456 | D36: Gauteng | E36: Sandton | F36: 45048 | G36: Frequent | H36: =TRUE()
A37: 65478 | B37: Refilwe Mahlangu | C37: +27472070827 | D37: Gauteng | E37: Centurion | F37: 45648 | G37: Occasional | H37: =FALSE()
A38: 88465 | B38: Johan Khumalo | C38: +27477854377 | D38: Limpopo | E38: Mokopane | F38: 44643 | G38: Dormant | H38: =TRUE()
A39: 135261 | B39: Mandla Adams | C39: +27477706434 | D39: KwaZulu-Natal | E39: Richards Bay | F39: 45519 | G39: Occasional | H39: =TRUE()
A40: 175273 | B40: Megan Zulu | C40: +27477656488 | D40: KwaZulu-Natal | E40: Umhlanga | F40: 44594 | G40: Occasional | H40: =TRUE()
A41: 136537 | B41: Sipho Nkosi | C41: +27478279462 | D41: Gauteng | E41: Sandton | F41: 44365 | G41: Dormant | H41: =TRUE()
A42: 177146 | B42: Johan Tshabalala | C42: +27479602965 | D42: KwaZulu-Natal | E42: Umhlanga | F42: 45261 | G42: Dormant | H42: =TRUE()
A43: 154653 | B43: Naledi Petersen | C43: +27479744969 | D43: Eastern Cape | E43: East London | F43: 44237 | G43: Regular | H43: =TRUE()
A44: 42593 | B44: Daniel Daniels | C44: +27476530498 | D44: Mpumalanga | E44: Middelburg | F44: 45645 | G44: Dormant | H44: =TRUE()
A45: 217333 | B45: Pieter Khumalo | C45: +27473512155 | D45: Limpopo | E45: Mokopane | F45: 45784 | G45: Regular | H45: =TRUE()
A46: 298065 | B46: Nomvula Molefe | C46: +27472995586 | D46: KwaZulu-Natal | E46: Umhlanga | F46: 44869 | G46: Occasional | H46: =TRUE()
A47: 297466 | B47: Anika Venter | C47: +27477111466 | D47: Western Cape | E47: Bellville | F47: 46050 | G47: Dormant | H47: =TRUE()
A48: 217463 | B48: Liam Mahlangu | C48: +27478856883 | D48: Gauteng | E48: Sandton | F48: 44557 | G48: Dormant | H48: =FALSE()
A49: 362902 | B49: Megan Steyn | C49: +27472232773 | D49: Mpumalanga | E49: Secunda | F49: 44248 | G49: Occasional | H49: =TRUE()
...

Sheet Couriers
A1: courier_id | B1: courier_name | C1: region | D1: vehicle_type | E1: hired_date
A2: 1 | B2: Jenna Talbot | C2: KwaZulu-Natal | D2: Motorcycle | E2: 43920
A3: 2 | B3: Mr Julian Carroll | C3: Limpopo | D3: 4-Ton Truck | E3: 43448
A4: 3 | B4: Gerard Chamberlain | C4: Gauteng | D4: Motorcycle | E4: 44238
A5: 4 | B5: Alex Hughes-Smith | C5: Gauteng | D5: Motorcycle | E5: 43858
A6: 5 | B6: Leigh Burgess | C6: Gauteng | D6: 4-Ton Truck | E6: 44675
A7: 6 | B7: Mr Phillip Lloyd | C7: Eastern Cape | D7: Panel Van | E7: 43690
A8: 7 | B8: Dr Peter Bevan | C8: North West | D8: 1-Ton Bakkie | E8: 43768
A9: 8 | B9: Mr Julian Browne | C9: Gauteng | D9: Motorcycle | E9: 45652
A10: 9 | B10: Brett Hill | C10: Limpopo | D10: Motorcycle | E10: 45313
A11: 10 | B11: Joel Stephens | C11: Gauteng | D11: Motorcycle | E11: 45261
A12: 11 | B12: Dr Stewart Sharp | C12: KwaZulu-Natal | D12: 1-Ton Bakkie | E12: 43982
A13: 12 | B13: Allan Burke | C13: Eastern Cape | D13: Panel Van | E13: 45643
... A501: 500 | B501: Maurice Graham-Faulkner | C501: Gauteng | D501: Panel Van | E501: 44989
